Workbook

Sheet Dashboard
B2: Borderless Project — 2025 Event Performance Dashboard
B3: Attendance, revenue, and engagement across all 2025 events
B5: Total Events | D5: Total Attendance | F5: Total Revenue | H5: Net Revenue | J5: Avg Attendance Rate
B6: =Summary!$B$55 -> 50 | D6: =Summary!$B$56 -> 26515 | F6: =Summary!$B$57 -> 861071.52 | H6: =Summary!$B$58 -> 810253.09 | J6: =Summary!$B$59 -> 0.70259375

Sheet Events
A1: Event_ID | B1: Event_Name | C1: Date | D1: Day_of_Week | E1: Month | F1: Start_Time | G1: Event_Type | H1: Genre | I1: Artist | J1: Venue | K1: City | L1: Capacity | M1: Tickets_Sold | N1: Attendance | O1: Attendance_Rate | P1: Ticket_Price | Q1: Ticket_Revenue | R1: Merch_Sales | S1: Total_Revenue | T1: Marketing_Spend | U1: Net_Revenue | V1: Social_Media_Impressions
A2: BL-001 | B2: Onyx Sol — Showcase | C2: 45661 | D2: =TEXT(C2,"dddd") -> Saturday | E2: =TEXT(C2,"mmm") -> Jan | F2: 19:00 | G2: Showcase | H2: Afrobeats | I2: Onyx Sol | J2: 1015 Folsom | K2: San Francisco | L2: 700 | M2: 572 | N2: 552 | O2: =N2/L2 -> 0.78857143 | P2: 18 | Q2: =M2*P2 -> 10296 | R2: 2294.78 | S2: =Q2+R2 -> 12590.78 | T2: 250.85 | U2: =S2-T2 -> 12339.93 | V2: 8340
A3: BL-002 | B3: Lumen Cruz — Festival Stage | C3: 45668 | D3: =TEXT(C3,"dddd") -> Saturday | E3: =TEXT(C3,"mmm") -> Jan | F3: 20:00 | G3: Festival Stage | H3: Electronic | I3: Lumen Cruz | J3: Harlow's | K3: Sacramento | L3: 450 | M3: 354 | N3: 337 | O3: =N3/L3 -> 0.74888889 | P3: 30 | Q3: =M3*P3 -> 10620 | R3: 1021.49 | S3: =Q3+R3 -> 11641.49 | T3: 448.77 | U3: =S3-T3 -> 11192.72 | V3: 57561
A4: BL-003 | B4: Wilder Vaughn — Concert | C4: 45672 | D4: =TEXT(C4,"dddd") -> Wednesday | E4: =TEXT(C4,"mmm") -> Jan | F4: 21:00 | G4: Concert | H4: Afrobeats | I4: Wilder Vaughn | J4: The Marsh | K4: Berkeley | L4: 200 | M4: 119 | N4: 102 | O4: =N4/L4 -> 0.51 | P4: 25 | Q4: =M4*P4 -> 2975 | R4: 533.7 | S4: =Q4+R4 -> 3508.7 | T4: 1189.63 | U4: =S4-T4 -> 2319.07 | V4: 52117
A5: BL-004 | B5: Onyx Marsh — Concert | C5: 45679 | D5: =TEXT(C5,"dddd") -> Wednesday | E5: =TEXT(C5,"mmm") -> Jan | F5: 21:00 | G5: Concert | H5: Afrobeats | I5: Onyx Marsh | J5: Ace of Spades | K5: Sacramento | L5: 1000 | M5: 663 | N5: 635 | O5: =N5/L5 -> 0.635 | P5: 20 | Q5: =M5*P5 -> 13260 | R5: 2010.29 | S5: =Q5+R5 -> 15270.29 | T5: 535.21 | U5: =S5-T5 -> 14735.08 | V5: 18217
A6: BL-005 | B6: Juniper Cruz — Festival Stage | C6: 45686 | D6: =TEXT(C6,"dddd") -> Wednesday | E6: =TEXT(C6,"mmm") -> Jan | F6: 19:30 | G6: Festival Stage | H6: Indie | I6: Juniper Cruz | J6: The Ritz | K6: San Jose | L6: 700 | M6: 638 | N6: 588 | O6: =N6/L6 -> 0.84 | P6: 28 | Q6: =M6*P6 -> 17864 | R6: 3112.19 | S6: =Q6+R6 -> 20976.19 | T6: 1441.6 | U6: =S6-T6 -> 19534.59 | V6: 16055
A7: BL-006 | B7: Halcyon Storm — Showcase | C7: 45693 | D7: =TEXT(C7,"dddd") -> Wednesday | E7: =TEXT(C7,"mmm") -> Feb | F7: 21:30 | G7: Showcase | H7: Pop | I7: Halcyon Storm | J7: Starline Social Club | K7: Oakland | L7: 300 | M7: 261 | N7: 226 | O7: =N7/L7 -> 0.75333333 | P7: 20 | Q7: =M7*P7 -> 5220 | R7: 589.82 | S7: =Q7+R7 -> 5809.82 | T7: 1098.19 | U7: =S7-T7 -> 4711.63 | V7: 17976
A8: BL-007 | B8: Kairo Marsh — Concert | C8: 45700 | D8: =TEXT(C8,"dddd") -> Wednesday | E8: =TEXT(C8,"mmm") -> Feb | F8: 20:00 | G8: Concert | H8: Latin | I8: Kairo Marsh | J8: Fox Theater | K8: Oakland | L8: 2800 | M8: 1567 | N8: 1470 | O8: =N8/L8 -> 0.525 | P8: 18 | Q8: =M8*P8 -> 28206 | R8: 4750.24 | S8: =Q8+R8 -> 32956.24 | T8: 1153.42 | U8: =S8-T8 -> 31802.82 | V8: 29678
A9: BL-008 | B9: Indigo Grey — Concert | C9: 45707 | D9: =TEXT(C9,"dddd") -> Wednesday | E9: =TEXT(C9,"mmm") -> Feb | F9: 19:30 | G9: Concert | H9: Pop | I9: Indigo Grey | J9: Harlow's | K9: Sacramento | L9: 450 | M9: 248 | N9: 234 | O9: =N9/L9 -> 0.52 | P9: 25 | Q9: =M9*P9 -> 6200 | R9: 1374.4 | S9: =Q9+R9 -> 7574.4 | T9: 1419.14 | U9: =S9-T9 -> 6155.26 | V9: 31937
A10: BL-009 | B10: Solace Vaughn — Listening Party | C10: 45715 | D10: =TEXT(C10,"dddd") -> Thursday | E10: =TEXT(C10,"mmm") -> Feb | F10: 20:00 | G10: Listening Party | H10: Indie | I10: Solace Vaughn | J10: The Ritz | K10: San Jose | L10: 700 | M10: 646 | N10: 626 | O10: =N10/L10 -> 0.89428571 | P10: 28 | Q10: =M10*P10 -> 18088 | R10: 2315.4 | S10: =Q10+R10 -> 20403.4 | T10: 378.99 | U10: =S10-T10 -> 20024.41 | V10: 23689
A11: BL-010 | B11: Miel Vaughn — Festival Stage | C11: 45719 | D11: =TEXT(C11,"dddd") -> Monday | E11: =TEXT(C11,"mmm") -> Mar | F11: 19:00 | G11: Festival Stage | H11: R&B | I11: Miel Vaughn | J11: The Ritz | K11: San Jose | L11: 700 | M11: 547 | N11: 498 | O11: =N11/L11 -> 0.71142857 | P11: 40 | Q11: =M11*P11 -> 21880 | R11: 1117.05 | S11: =Q11+R11 -> 22997.05 | T11: 1044.28 | U11: =S11-T11 -> 21952.77 | V11: 37575
A12: BL-011 | B12: Wilder Marsh — Album Release | C12: 45726 | D12: =TEXT(C12,"dddd") -> Monday | E12: =TEXT(C12,"mmm") -> Mar | F12: 21:00 | G12: Album Release | H12: Latin | I12: Wilder Marsh | J12: Harlow's | K12: Sacramento | L12: 450 | M12: 305 | N12: 260 | O12: =N12/L12 -> 0.57777778 | P12: 40 | Q12: =M12*P12 -> 12200 | R12: 659.23 | S12: =Q12+R12 -> 12859.23 | T12: 552.35 | U12: =S12-T12 -> 12306.88 | V12: 7046
A13: BL-012 | B13: Onyx Cruz — Album Release | C13: 45731 | D13: =TEXT(C13,"dddd") -> Saturday | E13: =TEXT(C13,"mmm") -> Mar | F13: 19:00 | G13: Album Release | H13: R&B | I13: Onyx Cruz | J13: Great American Music Hall | K13: San Francisco | L13: 470 | M13: 397 | N13: 344 | O13: =N13/L13 -> 0.73191489 | P13: 35 | Q13: =M13*P13 -> 13895 | R13: 892.16 | S13: =Q13+R13 -> 14787.16 | T13: 956.76 | U13: =S13-T13 -> 13830.4 | V13: 26202
... A51: BL-050 | B51: Solace Lane — Concert | C51: 46017 | D51: =TEXT(C51,"dddd") -> Friday | E51: =TEXT(C51,"mmm") -> Dec | F51: 20:30 | G51: Concert | H51: Pop | I51: Solace Lane | J51: El Rey Theatre | K51: Los Angeles | L51: 850 | M51: 617 | N51: 577 | O51: =N51/L51 -> 0.67882353 | P51: 30 | Q51: =M51*P51 -> 18510 | R51: 2977.92 | S51: =Q51+R51 -> 21487.92 | T51: 1080.15 | U51: =S51-T51 -> 20407.77 | V51: 28925

Sheet Summary
A1: Monthly Performance
A3: Month | B3: Events | C3: Total Attendance | D3: Total Revenue | E3: Avg Attendance Rate
A4: Jan | B4: =COUNTIF(Events!$E$2:$E$51,A4) -> 5 | C4: =SUMIF(Events!$E$2:$E$51,A4,Events!$N$2:$N$51) -> 2214 | D4: =SUMIF(Events!$E$2:$E$51,A4,Events!$S$2:$S$51) -> 63987.45 | E4: =IFERROR(AVERAGEIF(Events!$E$2:$E$51,A4,Events!$O$2:$O$51),0) -> 0.70449206
A5: Feb | B5: =COUNTIF(Events!$E$2:$E$51,A5) -> 4 | C5: =SUMIF(Events!$E$2:$E$51,A5,Events!$N$2:$N$51) -> 2556 | D5: =SUMIF(Events!$E$2:$E$51,A5,Events!$S$2:$S$51) -> 66743.86 | E5: =IFERROR(AVERAGEIF(Events!$E$2:$E$51,A5,Events!$O$2:$O$51),0) -> 0.67315476
A6: Mar | B6: =COUNTIF(Events!$E$2:$E$51,A6) -> 5 | C6: =SUMIF(Events!$E$2:$E$51,A6,Events!$N$2:$N$51) -> 2063 | D6: =SUMIF(Events!$E$2:$E$51,A6,Events!$S$2:$S$51) -> 74466.52 | E6: =IFERROR(AVERAGEIF(Events!$E$2:$E$51,A6,Events!$O$2:$O$51),0) -> 0.71005153
A7: Apr | B7: =COUNTIF(Events!$E$2:$E$51,A7) -> 3 | C7: =SUMIF(Events!$E$2:$E$51,A7,Events!$N$2:$N$51) -> 1163 | D7: =SUMIF(Events!$E$2:$E$51,A7,Events!$S$2:$S$51) -> 37848.67 | E7: =IFERROR(AVERAGEIF(Events!$E$2:$E$51,A7,Events!$O$2:$O$51),0) -> 0.66416558
A8: May | B8: =COUNTIF(Events!$E$2:$E$51,A8) -> 4 | C8: =SUMIF(Events!$E$2:$E$51,A8,Events!$N$2:$N$51) -> 2370 | D8: =SUMIF(Events!$E$2:$E$51,A8,Events!$S$2:$S$51) -> 78035.57 | E8: =IFERROR(AVERAGEIF(Events!$E$2:$E$51,A8,Events!$O$2:$O$51),0) -> 0.59784091
A9: Jun | B9: =COUNTIF(Events!$E$2:$E$51,A9) -> 5 | C9: =SUMIF(Events!$E$2:$E$51,A9,Events!$N$2:$N$51) -> 2245 | D9: =SUMIF(Events!$E$2:$E$51,A9,Events!$S$2:$S$51) -> 68034.13 | E9: =IFERROR(AVERAGEIF(Events!$E$2:$E$51,A9,Events!$O$2:$O$51),0) -> 0.72151198
A10: Jul | B10: =COUNTIF(Events!$E$2:$E$51,A10) -> 4 | C10: =SUMIF(Events!$E$2:$E$51,A10,Events!$N$2:$N$51) -> 1421 | D10: =SUMIF(Events!$E$2:$E$51,A10,Events!$S$2:$S$51) -> 59735.11 | E10: =IFERROR(AVERAGEIF(Events!$E$2:$E$51,A10,Events!$O$2:$O$51),0) -> 0.79304412
A11: Aug | B11: =COUNTIF(Events!$E$2:$E$51,A11) -> 5 | C11: =SUMIF(Events!$E$2:$E$51,A11,Events!$N$2:$N$51) -> 2206 | D11: =SUMIF(Events!$E$2:$E$51,A11,Events!$S$2:$S$51) -> 74679.46 | E11: =IFERROR(AVERAGEIF(Events!$E$2:$E$51,A11,Events!$O$2:$O$51),0) -> 0.66428571
A12: Sep | B12: =COUNTIF(Events!$E$2:$E$51,A12) -> 4 | C12: =SUMIF(Events!$E$2:$E$51,A12,Events!$N$2:$N$51) -> 3032 | D12: =SUMIF(Events!$E$2:$E$51,A12,Events!$S$2:$S$51) -> 67554.34 | E12: =IFERROR(AVERAGEIF(Events!$E$2:$E$51,A12,Events!$O$2:$O$51),0) -> 0.67680032
A13: Oct | B13: =COUNTIF(Events!$E$2:$E$51,A13) -> 4 | C13: =SUMIF(Events!$E$2:$E$51,A13,Events!$N$2:$N$51) -> 3618 | D13: =SUMIF(Events!$E$2:$E$51,A13,Events!$S$2:$S$51) -> 132183.88 | E13: =IFERROR(AVERAGEIF(Events!$E$2:$E$51,A13,Events!$O$2:$O$51),0) -> 0.74767477
A14: Nov | B14: =COUNTIF(Events!$E$2:$E$51,A14) -> 4 | C14: =SUMIF(Events!$E$2:$E$51,A14,Events!$N$2:$N$51) -> 2471 | D14: =SUMIF(Events!$E$2:$E$51,A14,Events!$S$2:$S$51) -> 91332.62 | E14: =IFERROR(AVERAGEIF(Events!$E$2:$E$51,A14,Events!$O$2:$O$51),0) -> 0.73665033
A15: Dec | B15: =COUNTIF(Events!$E$2:$E$51,A15) -> 3 | C15: =SUMIF(Events!$E$2:$E$51,A15,Events!$N$2:$N$51) -> 1156 | D15: =SUMIF(Events!$E$2:$E$51,A15,Events!$S$2:$S$51) -> 46469.91 | E15: =IFERROR(AVERAGEIF(Events!$E$2:$E$51,A15,Events!$O$2:$O$51),0) -> 0.74494118
A18: Performance by Genre
A20: Genre | B20: Events | C20: Total Revenue | D20: Avg Attendance Rate | E20: Total Attendance
A21: Hip-Hop | B21: =COUNTIF(Events!$H$2:$H$51,A21) -> 4 | C21: =SUMIF(Events!$H$2:$H$51,A21,Events!$S$2:$S$51) -> 77125.11 | D21: =IFERROR(AVERAGEIF(Events!$H$2:$H$51,A21,Events!$O$2:$O$51),0) -> 0.74094156 | E21: =SUMIF(Events!$H$2:$H$51,A21,Events!$N$2:$N$51) -> 2174
A22: R&B | B22: =COUNTIF(Events!$H$2:$H$51,A22) -> 8 | C22: =SUMIF(Events!$H$2:$H$51,A22,Events!$S$2:$S$51) -> 104898.26 | D22: =IFERROR(AVERAGEIF(Events!$H$2:$H$51,A22,Events!$O$2:$O$51),0) -> 0.69422099 | E22: =SUMIF(Events!$H$2:$H$51,A22,Events!$N$2:$N$51) -> 3108
A23: Indie | B23: =COUNTIF(Events!$H$2:$H$51,A23) -> 3 | C23: =SUMIF(Events!$H$2:$H$51,A23,Events!$S$2:$S$51) -> 61059.37 | D23: =IFERROR(AVERAGEIF(Events!$H$2:$H$51,A23,Events!$O$2:$O$51),0) -> 0.84857143 | E23: =SUMIF(Events!$H$2:$H$51,A23,Events!$N$2:$N$51) -> 1782
A24: Electronic | B24: =COUNTIF(Events!$H$2:$H$51,A24) -> 10 | C24: =SUMIF(Events!$H$2:$H$51,A24,Events!$S$2:$S$51) -> 266153.05 | D24: =IFERROR(AVERAGEIF(Events!$H$2:$H$51,A24,Events!$O$2:$O$51),0) -> 0.72926771 | E24: =SUMIF(Events!$H$2:$H$51,A24,Events!$N$2:$N$51) -> 7686
A25: Afrobeats | B25: =COUNTIF(Events!$H$2:$H$51,A25) -> 7 | C25: =SUMIF(Events!$H$2:$H$51,A25,Events!$S$2:$S$51) -> 69843.11 | D25: =IFERROR(AVERAGEIF(Events!$H$2:$H$51,A25,Events!$O$2:$O$51),0) -> 0.67742218 | E25: =SUMIF(Events!$H$2:$H$51,A25,Events!$N$2:$N$51) -> 2435
A26: Pop | B26: =COUNTIF(Events!$H$2:$H$51,A26) -> 7 | C26: =SUMIF(Events!$H$2:$H$51,A26,Events!$S$2:$S$51) -> 111378.32 | D26: =IFERROR(AVERAGEIF(Events!$H$2:$H$51,A26,Events!$O$2:$O$51),0) -> 0.65836001 | E26: =SUMIF(Events!$H$2:$H$51,A26,Events!$N$2:$N$51) -> 3733
A27: Alt Rock | B27: =COUNTIF(Events!$H$2:$H$51,A27) -> 4 | C27: =SUMIF(Events!$H$2:$H$51,A27,Events!$S$2:$S$51) -> 60043.42 | D27: =IFERROR(AVERAGEIF(Events!$H$2:$H$51,A27,Events!$O$2:$O$51),0) -> 0.63369958 | E27: =SUMIF(Events!$H$2:$H$51,A27,Events!$N$2:$N$51) -> 1904
A28: Latin | B28: =COUNTIF(Events!$H$2:$H$51,A28) -> 7 | C28: =SUMIF(Events!$H$2:$H$51,A28,Events!$S$2:$S$51) -> 110570.88 | D28: =IFERROR(AVERAGEIF(Events!$H$2:$H$51,A28,Events!$O$2:$O$51),0) -> 0.69835548 | E28: =SUMIF(Events!$H$2:$H$51,A28,Events!$N$2:$N$51) -> 3693
A31: Performance by Day of Week
A33: Day | B33: Events | C33: Avg Attendance Rate | D33: Total Revenue
A34: Monday | B34: =COUNTIF(Events!$D$2:$D$51,A34) -> 12 | C34: =IFERROR(AVERAGEIF(Events!$D$2:$D$51,A34,Events!$O$2:$O$51),0) -> 0.73194761 | D34: =SUMIF(Events!$D$2:$D$51,A34,Events!$S$2:$S$51) -> 202299.59
A35: Tuesday | B35: =COUNTIF(Events!$D$2:$D$51,A35) -> 4 | C35: =IFERROR(AVERAGEIF(Events!$D$2:$D$51,A35,Events!$O$2:$O$51),0) -> 0.6592298 | D35: =SUMIF(Events!$D$2:$D$51,A35,Events!$S$2:$S$51) -> 135543.6
A36: Wednesday | B36: =COUNTIF(Events!$D$2:$D$51,A36) -> 10 | C36: =IFERROR(AVERAGEIF(Events!$D$2:$D$51,A36,Events!$O$2:$O$51),0) -> 0.6765461 | D36: =SUMIF(Events!$D$2:$D$51,A36,Events!$S$2:$S$51) -> 122194.22
A37: Thursday | B37: =COUNTIF(Events!$D$2:$D$51,A37) -> 3 | C37: =IFERROR(AVERAGEIF(Events!$D$2:$D$51,A37,Events!$O$2:$O$51),0) -> 0.74568783 | D37: =SUMIF(Events!$D$2:$D$51,A37,Events!$S$2:$S$51) -> 33826.55
A38: Friday | B38: =COUNTIF(Events!$D$2:$D$51,A38) -> 4 | C38: =IFERROR(AVERAGEIF(Events!$D$2:$D$51,A38,Events!$O$2:$O$51),0) -> 0.66327731 | D38: =SUMIF(Events!$D$2:$D$51,A38,Events!$S$2:$S$51) -> 74033.95
A39: Saturday | B39: =COUNTIF(Events!$D$2:$D$51,A39) -> 13 | C39: =IFERROR(AVERAGEIF(Events!$D$2:$D$51,A39,Events!$O$2:$O$51),0) -> 0.71465471 | D39: =SUMIF(Events!$D$2:$D$51,A39,Events!$S$2:$S$51) -> 231573.37
A40: Sunday | B40: =COUNTIF(Events!$D$2:$D$51,A40) -> 4 | C40: =IFERROR(AVERAGEIF(Events!$D$2:$D$51,A40,Events!$O$2:$O$51),0) -> 0.69081303 | D40: =SUMIF(Events!$D$2:$D$51,A40,Events!$S$2:$S$51) -> 61600.24
A43: Performance by City
A45: City | B45: Events | C45: Total Revenue | D45: Avg Attendance Rate
A46: San Francisco | B46: =COUNTIF(Events!$K$2:$K$51,A46) -> 8 | C46: =SUMIF(Events!$K$2:$K$51,A46,Events!$S$2:$S$51) -> 97496.53 | D46: =IFERROR(AVERAGEIF(Events!$K$2:$K$51,A46,Events!$O$2:$O$51),0) -> 0.7567272
A47: Oakland | B47: =COUNTIF(Events!$K$2:$K$51,A47) -> 7 | C47: =SUMIF(Events!$K$2:$K$51,A47,Events!$S$2:$S$51) -> 208296.31 | D47: =IFERROR(AVERAGEIF(Events!$K$2:$K$51,A47,Events!$O$2:$O$51),0) -> 0.71291126
A48: Berkeley | B48: =COUNTIF(Events!$K$2:$K$51,A48) -> 8 | C48: =SUMIF(Events!$K$2:$K$51,A48,Events!$S$2:$S$51) -> 143779.62 | D48: =IFERROR(AVERAGEIF(Events!$K$2:$K$51,A48,Events!$O$2:$O$51),0) -> 0.63919643
A49: Los Angeles | B49: =COUNTIF(Events!$K$2:$K$51,A49) -> 9 | C49: =SUMIF(Events!$K$2:$K$51,A49,Events!$S$2:$S$51) -> 166755.74 | D49: =IFERROR(AVERAGEIF(Events!$K$2:$K$51,A49,Events!$O$2:$O$51),0) -> 0.71031559
A50: San Jose | B50: =COUNTIF(Events!$K$2:$K$51,A50) -> 7 | C50: =SUMIF(Events!$K$2:$K$51,A50,Events!$S$2:$S$51) -> 107514.34 | D50: =IFERROR(AVERAGEIF(Events!$K$2:$K$51,A50,Events!$O$2:$O$51),0) -> 0.75497959
...
